Workbook

Sheet Task của Hưng
A1: STT | B1: WBS | C1: UID | D1: Sprint | E1: PBI | F1: Nhóm công việc | G1: Tên task | H1: Bắt đầu | I1: Kết thúc | J1: Thời lượng (h) | K1: Công của Hưng (h) | L1: Ước lượng cũ (h) | M1: Cơ sở ước lượng | N1: Trạng thái
A2: 1 | B2: 2.2.4 | C2: 762 | D2: Sprint 1 | E2: PBI-S01 | F2: PBI S01 – Chức năng và công việc hỗ trợ | G2: Phân tích yêu cầu giao diện | H2: 46275.625 | I2: 46275.667 | J2: 1 | K2: 1 | L2: 8 | M2: Một component/màn hình React hoặc cấu hình nhỏ; dùng thư viện và layout chung. | N2: Chờ nhóm rà soát
A3: 2 | B3: 2.2.9 | C3: 763 | D3: Sprint 1 | E3: PBI-S01 | F3: PBI S01 – Chức năng và công việc hỗ trợ | G3: Khởi tạo project frontend | H3: 46275.667 | I3: 46275.708 | J3: 1 | K3: 1 | L3: 8 | M3: Một component/màn hình React hoặc cấu hình nhỏ; dùng thư viện và layout chung. | N3: Chờ nhóm rà soát
A4: 3 | B4: 2.2.13 | C4: 764 | D4: Sprint 1 | E4: PBI-S01 | F4: PBI S01 – Chức năng và công việc hỗ trợ | G4: Thiết lập cấu trúc thư mục frontend | H4: 46276.333 | I4: 46276.354 | J4: 0.5 | K4: 0.5 | L4: 8 | M4: Một component/màn hình React hoặc cấu hình nhỏ; dùng thư viện và layout chung. | N4: Chờ nhóm rà soát
A5: 4 | B5: 2.2.17 | C5: 766 | D5: Sprint 1 | E5: PBI-S01 | F5: PBI S01 – Chức năng và công việc hỗ trợ | G5: Thiết lập component base | H5: 46276.354 | I5: 46276.396 | J5: 1 | K5: 1 | L5: 8 | M5: Một component/màn hình React hoặc cấu hình nhỏ; dùng thư viện và layout chung. | N5: Chờ nhóm rà soát
A6: 5 | B6: 2.2.20 | C6: 767 | D6: Sprint 1 | E6: PBI-S01 | F6: PBI S01 – Chức năng và công việc hỗ trợ | G6: Thiết lập layout chung | H6: 46276.396 | I6: 46276.438 | J6: 1 | K6: 1 | L6: 8 | M6: Một component/màn hình React hoặc cấu hình nhỏ; dùng thư viện và layout chung. | N6: Chờ nhóm rà soát
A7: 6 | B7: 2.2.25 | C7: 769 | D7: Sprint 1 | E7: PBI-S01 | F7: PBI S01 – Chức năng và công việc hỗ trợ | G7: Thiết lập form validation | H7: 46276.438 | I7: 46276.479 | J7: 1 | K7: 1 | L7: 8 | M7: Một component/màn hình React hoặc cấu hình nhỏ; dùng thư viện và layout chung. | N7: Chờ nhóm rà soát
A8: 7 | B8: 2.2.30 | C8: 770 | D8: Sprint 1 | E8: PBI-S01 | F8: PBI S01 – Chức năng và công việc hỗ trợ | G8: Thiết lập HTTP client | H8: 46276.479 | I8: 46276.562 | J8: 1 | K8: 1 | L8: 16 | M8: Một component/màn hình React hoặc cấu hình nhỏ; dùng thư viện và layout chung. | N8: Chờ nhóm rà soát
A9: 8 | B9: 2.2.37 | C9: 776 | D9: Sprint 1 | E9: PBI-S01 | F9: PBI S01 – Chức năng và công việc hỗ trợ | G9: Tạo trang danh sách dịch vụ | H9: 46276.615 | I9: 46276.656 | J9: 1 | K9: 1 | L9: 8 | M9: Một component/màn hình React hoặc cấu hình nhỏ; dùng thư viện và layout chung. | N9: Chờ nhóm rà soát
A10: 9 | B10: 2.2.43 | C10: 765 | D10: Sprint 1 | E10: PBI-S01 | F10: PBI S01 – Chức năng và công việc hỗ trợ | G10: Thiết lập routing | H10: 46276.656 | I10: 46276.698 | J10: 1 | K10: 1 | L10: 8 | M10: Một component/màn hình React hoặc cấu hình nhỏ; dùng thư viện và layout chung. | N10: Chờ nhóm rà soát
A11: 10 | B11: 2.2.49 | C11: 768 | D11: Sprint 1 | E11: PBI-S01 | F11: PBI S01 – Chức năng và công việc hỗ trợ | G11: Thiết lập responsive grid | H11: 46276.698 | I11: 46279.365 | J11: 1 | K11: 1 | L11: 8 | M11: Một component/màn hình React hoặc cấu hình nhỏ; dùng thư viện và layout chung. | N11: Chờ nhóm rà soát
A12: 11 | B12: 2.2.54 | C12: 772 | D12: Sprint 1 | E12: PBI-S01 | F12: PBI S01 – Chức năng và công việc hỗ trợ | G12: Tạo trang Landing | H12: 46279.365 | I12: 46279.406 | J12: 1 | K12: 1 | L12: 8 | M12: Một component/màn hình React hoặc cấu hình nhỏ; dùng thư viện và layout chung. | N12: Chờ nhóm rà soát
A13: 12 | B13: 2.2.57 | C13: 773 | D13: Sprint 1 | E13: PBI-S01 | F13: PBI S01 – Chức năng và công việc hỗ trợ | G13: Tạo Header | H13: 46279.406 | I13: 46279.427 | J13: 0.5 | K13: 0.5 | L13: 8 | M13: Một component/màn hình React hoặc cấu hình nhỏ; dùng thư viện và layout chung. | N13: Chờ nhóm rà soát
... A17: 16 | B17: 2.2.69 | C17: 902 | D17: Sprint 1 | E17: PBI-S01 | F17: PBI S01 – Chức năng và công việc hỗ trợ | G17: Thiết lập CI/CD React và build frontend tự động | H17: 46279.552 | I17: 46279.594 | J17: 1 | K17: 1 | L17: 8 | M17: Một component/màn hình React hoặc cấu hình nhỏ; dùng thư viện và layout chung. | N17: Chờ nhóm rà soát
A18: 17 | B18: 2.3.1 | C18: 2024 | D18: Sprint 1 | E18: PBI-S01 | F18: Tích hợp, kiểm thử và Increment | G18: Tích hợp đầu-cuối Sprint 1: React ↔ FastAPI ↔ PostgreSQL | H18: 46281.365 | I18: 46281.448 | J18: 2 | K18: 2 | M18: Bổ sung để chức năng có thể tích hợp, kiểm thử và bàn giao trong Sprint. | N18: Chờ nhóm rà soát
A19: 18 | B19: 2.3.2 | C19: 2025 | D19: Sprint 1 | E19: PBI-S01 | F19: Tích hợp, kiểm thử và Increment | G19: Kiểm thử acceptance và hồi quy Sprint 1 | H19: 46281.448 | I19: 46281.573 | J19: 2 | K19: 2 | M19: Bổ sung để chức năng có thể tích hợp, kiểm thử và bàn giao trong Sprint. | N19: Chờ nhóm rà soát
A20: 19 | B20: 2.3.4 | C20: 2027 | D20: Sprint 1 | E20: PBI-S01 | F20: Tích hợp, kiểm thử và Increment | G20: Sửa lỗi frontend theo kết quả kiểm thử Sprint 1 | H20: 46281.656 | I20: 46281.698 | J20: 1 | K20: 1 | M20: Bổ sung để chức năng có thể tích hợp, kiểm thử và bàn giao trong Sprint. | N20: Chờ nhóm rà soát
A21: 20 | B21: 2.3.6 | C21: 2029 | D21: Sprint 1 | E21: PBI-S01 | F21: Tích hợp, kiểm thử và Increment | G21: Retest, xác minh Definition of Done Sprint 1 | H21: 46281.698 | I21: 46282.365 | J21: 1 | K21: 1 | M21: Bổ sung để chức năng có thể tích hợp, kiểm thử và bàn giao trong Sprint. | N21: Chờ nhóm rà soát
A22: 21 | B22: 2.4.1 | C22: 2016 | D22: Sprint 1 | E22: PBI-S01 | F22: Họp nhóm hằng tuần | G22: Họp tuần 1 – báo cáo tiến độ, demo và thống nhất việc tiếp theo | H22: 46282.365 | I22: 46282.448 | J22: 2 | K22: 2 | N22: Chờ nhóm rà soát
A23: 22 | B23: 3.2.3 | C23: 771 | D23: Sprint 2 | E23: PBI-S02 | F23: PBI S02 – Chức năng và công việc hỗ trợ | G23: Thiết lập xử lý token | H23: 46282.542 | I23: 46282.583 | J23: 1 | K23: 1 | L23: 8 | M23: Một component/màn hình React hoặc cấu hình nhỏ; dùng thư viện và layout chung. | N23: Chờ nhóm rà soát
A24: 23 | B24: 3.2.14 | C24: 778 | D24: Sprint 2 | E24: PBI-S02 | F24: PBI S02 – Chức năng và công việc hỗ trợ | G24: Tạo trang đăng ký | H24: 46282.698 | I24: 46283.365 | J24: 1 | K24: 1 | L24: 8 | M24: Một component/màn hình React hoặc cấu hình nhỏ; dùng thư viện và layout chung. | N24: Chờ nhóm rà soát
A25: 24 | B25: 3.2.17 | C25: 779 | D25: Sprint 2 | E25: PBI-S02 | F25: PBI S02 – Chức năng và công việc hỗ trợ | G25: Tạo trang đăng nhập | H25: 46283.385 | I25: 46283.427 | J25: 1 | K25: 1 | L25: 8 | M25: Một component/màn hình React hoặc cấu hình nhỏ; dùng thư viện và layout chung. | N25: Chờ nhóm rà soát
A26: 25 | B26: 3.2.19 | C26: 781 | D26: Sprint 2 | E26: PBI-S02 | F26: PBI S02 – Chức năng và công việc hỗ trợ | G26: Tạo trang hồ sơ cá nhân | H26: 46283.458 | I26: 46283.5 | J26: 1 | K26: 1 | L26: 8 | M26: Một component/màn hình React hoặc cấu hình nhỏ; dùng thư viện và layout chung. | N26: Chờ nhóm rà soát
A27: 26 | B27: 3.2.21 | C27: 824 | D27: Sprint 2 | E27: PBI-S02 | F27: PBI S02 – Chức năng và công việc hỗ trợ | G27: Kết nối API đăng ký | H27: 46283.542 | I27: 46283.604 | J27: 1.5 | K27: 1.5 | L27: 8 | M27: Nối API và xử lý lỗi/token của luồng xác thực. | N27: Chờ nhóm rà soát
A28: 27 | B28: 3.2.23 | C28: 825 | D28: Sprint 2 | E28: PBI-S02 | F28: PBI S02 – Chức năng và công việc hỗ trợ | G28: Kết nối API đăng nhập | H28: 46283.667 | I28: 46286.354 | J28: 1.5 | K28: 1.5 | L28: 8 | M28: Nối API và xử lý lỗi/token của luồng xác thực. | N28: Chờ nhóm rà soát
A29: 28 | B29: 3.3.1 | C29: 2039 | D29: Sprint 2 | E29: PBI-S02 | F29: Tích hợp, kiểm thử và Increment | G29: Tích hợp đầu-cuối Sprint 2: React ↔ FastAPI ↔ PostgreSQL | H29: 46287.427 | I29: 46287.552 | J29: 2 | K29: 2 | M29: Bổ sung để chức năng có thể tích hợp, kiểm thử và bàn giao trong Sprint. | N29: Chờ nhóm rà soát
A30: 29 | B30: 3.3.2 | C30: 2040 | D30: Sprint 2 | E30: PBI-S02 | F30: Tích hợp, kiểm thử và Increment | G30: Kiểm thử acceptance và hồi quy Sprint 2 | H30: 46287.552 | I30: 46287.635 | J30: 2 | K30: 2 | M30: Bổ sung để chức năng có thể tích hợp, kiểm thử và bàn giao trong Sprint. | N30: Chờ nhóm rà soát
A31: 30 | B31: 3.3.4 | C31: 2042 | D31: Sprint 2 | E31: PBI-S02 | F31: Tích hợp, kiểm thử và Increment | G31: Sửa lỗi frontend theo kết quả kiểm thử Sprint 2 | H31: 46288.344 | I31: 46288.385 | J31: 1 | K31: 1 | M31: Bổ sung để chức năng có thể tích hợp, kiểm thử và bàn giao trong Sprint. | N31: Chờ nhóm rà soát
A32: 31 | B32: 3.3.6 | C32: 2044 | D32: Sprint 2 | E32: PBI-S02 | F32: Tích hợp, kiểm thử và Increment | G32: Retest, xác minh Definition of Done Sprint 2 | H32: 46288.385 | I32: 46288.427 | J32: 1 | K32: 1 | M32: Bổ sung để chức năng có thể tích hợp, kiểm thử và bàn giao trong Sprint. | N32: Chờ nhóm rà soát
A33: 32 | B33: 3.4.1 | C33: 2031 | D33: Sprint 2 | E33: PBI-S02 | F33: Họp nhóm hằng tuần | G33: Họp tuần 2 – báo cáo tiến độ, demo và thống nhất việc tiếp theo | H33: 46288.625 | I33: 46288.708 | J33: 2 | K33: 2 | N33: Chờ nhóm rà soát
A34: 33 | B34: 4.2.4 | C34: 786 | D34: Sprint 3 | E34: PBI-S03 | F34: PBI S03 – Chức năng và công việc hỗ trợ | G34: Tạo giao diện kiểm tra slot trống | H34: 46289.385 | I34: 46289.427 | J34: 1 | K34: 1 | L34: 8 | M34: Một component/màn hình React hoặc cấu hình nhỏ; dùng thư viện và layout chung. | N34: Chờ nhóm rà soát
A35: 34 | B35: 4.2.12 | C35: 782 | D35: Sprint 3 | E35: PBI-S03 | F35: PBI S03 – Chức năng và công việc hỗ trợ | G35: Tạo trang chọn dịch vụ | H35: 46289.448 | I35: 46289.49 | J35: 1 | K35: 1 | L35: 8 | M35: Một component/màn hình React hoặc cấu hình nhỏ; dùng thư viện và layout chung. | N35: Chờ nhóm rà soát
A36: 35 | B36: 4.2.17 | C36: 783 | D36: Sprint 3 | E36: PBI-S03 | F36: PBI S03 – Chức năng và công việc hỗ trợ | G36: Tạo giao diện chọn ngày | H36: 46289.49 | I36: 46289.573 | J36: 1 | K36: 1 | L36: 8 | M36: Một component/màn hình React hoặc cấu hình nhỏ; dùng thư viện và layout chung. | N36: Chờ nhóm rà soát
A37: 36 | B37: 4.2.21 | C37: 784 | D37: Sprint 3 | E37: PBI-S03 | F37: PBI S03 – Chức năng và công việc hỗ trợ | G37: Tạo giao diện chọn giờ | H37: 46289.573 | I37: 46289.615 | J37: 1 | K37: 1 | L37: 8 | M37: Một component/màn hình React hoặc cấu hình nhỏ; dùng thư viện và layout chung. | N37: Chờ nhóm rà soát
A38: 37 | B38: 4.2.24 | C38: 785 | D38: Sprint 3 | E38: PBI-S03 | F38: PBI S03 – Chức năng và công việc hỗ trợ | G38: Tạo giao diện chọn kỹ thuật viên | H38: 46289.615 | I38: 46289.656 | J38: 1 | K38: 1 | L38: 8 | M38: Một component/màn hình React hoặc cấu hình nhỏ; dùng thư viện và layout chung. | N38: Chờ nhóm rà soát
A39: 38 | B39: 4.2.25 | C39: 788 | D39: Sprint 3 | E39: PBI-S03 | F39: PBI S03 – Chức năng và công việc hỗ trợ | G39: Tạo màn hình xác nhận lịch | H39: 46289.656 | I39: 46289.698 | J39: 1 | K39: 1 | L39: 8 | M39: Một component/màn hình React hoặc cấu hình nhỏ; dùng thư viện và layout chung. | N39: Chờ nhóm rà soát
A40: 39 | B40: 4.2.26 | C40: 787 | D40: Sprint 3 | E40: PBI-S03 | F40: PBI S03 – Chức năng và công việc hỗ trợ | G40: Tạo form đặt lịch | H40: 46290.344 | I40: 46290.427 | J40: 2 | K40: 2 | L40: 8 | M40: Một màn hình/luồng có xử lý nghiệp vụ; dùng component chung, tích hợp đầu-cuối có task riêng. | N40: Chờ nhóm rà soát
A41: 40 | B41: 4.2.28 | C41: 789 | D41: Sprint 3 | E41: PBI-S03 | F41: PBI S03 – Chức năng và công việc hỗ trợ | G41: Tạo màn hình lịch đã đặt | H41: 46290.427 | I41: 46290.469 | J41: 1 | K41: 1 | L41: 8 | M41: Một component/màn hình React hoặc cấu hình nhỏ; dùng thư viện và layout chung. | N41: Chờ nhóm rà soát
A42: 41 | B42: 4.2.29 | C42: 790 | D42: Sprint 3 | E42: PBI-S03 | F42: PBI S03 – Chức năng và công việc hỗ trợ | G42: Tạo chức năng đổi lịch | H42: 46290.469 | I42: 46290.594 | J42: 2 | K42: 2 | L42: 16 | M42: Một màn hình/luồng có xử lý nghiệp vụ; dùng component chung, tích hợp đầu-cuối có task riêng. | N42: Chờ nhóm rà soát
A43: 42 | B43: 4.2.31 | C43: 791 | D43: Sprint 3 | E43: PBI-S03 | F43: PBI S03 – Chức năng và công việc hỗ trợ | G43: Tạo chức năng hủy lịch | H43: 46290.594 | I43: 46290.635 | J43: 1 | K43: 1 | L43: 8 | M43: Một component/màn hình React hoặc cấu hình nhỏ; dùng thư viện và layout chung. | N43: Chờ nhóm rà soát
...

Sheet Tổng hợp theo Sprint
A1: Sprint | B1: Mục tiêu Sprint | C1: Số task | D1: Công (h) | E1: Bắt đầu sớm nhất | F1: Kết thúc muộn nhất
A2: Sprint 1 | B2: Khách hàng xem danh sách và chi tiết dịch vụ trên bản web chạy được | C2: =COUNTIF('Task của Hưng'!D$2:D$109,A2) -> 21 | D2: =SUMIF('Task của Hưng'!D$2:D$109,A2,'Task của Hưng'!K$2:K$109) -> 22 | E2: =_xlfn.MINIFS('Task của Hưng'!H$2:H$109,'Task của Hưng'!D$2:D$109,A2) -> 46275.625 | F2: =_xlfn.MAXIFS('Task của Hưng'!I$2:I$109,'Task của Hưng'!D$2:D$109,A2) -> 46282.448
A3: Sprint 2 | B3: Khách hàng đăng ký, đăng nhập và quản lý hồ sơ | C3: =COUNTIF('Task của Hưng'!D$2:D$109,A3) -> 11 | D3: =SUMIF('Task của Hưng'!D$2:D$109,A3,'Task của Hưng'!K$2:K$109) -> 15 | E3: =_xlfn.MINIFS('Task của Hưng'!H$2:H$109,'Task của Hưng'!D$2:D$109,A3) -> 46282.542 | F3: =_xlfn.MAXIFS('Task của Hưng'!I$2:I$109,'Task của Hưng'!D$2:D$109,A3) -> 46288.708
A4: Sprint 3 | B4: Khách hàng đặt, đổi, hủy lịch; hệ thống chống trùng khung giờ | C4: =COUNTIF('Task của Hưng'!D$2:D$109,A4) -> 15 | D4: =SUMIF('Task của Hưng'!D$2:D$109,A4,'Task của Hưng'!K$2:K$109) -> 20 | E4: =_xlfn.MINIFS('Task của Hưng'!H$2:H$109,'Task của Hưng'!D$2:D$109,A4) -> 46289.385 | F4: =_xlfn.MAXIFS('Task của Hưng'!I$2:I$109,'Task của Hưng'!D$2:D$109,A4) -> 46295.708
A5: Sprint 4 | B5: Khách hàng đặt chỗ; nhân viên quản lý hàng chờ và lịch làm việc | C5: =COUNTIF('Task của Hưng'!D$2:D$109,A5) -> 16 | D5: =SUMIF('Task của Hưng'!D$2:D$109,A5,'Task của Hưng'!K$2:K$109) -> 21 | E5: =_xlfn.MINIFS('Task của Hưng'!H$2:H$109,'Task của Hưng'!D$2:D$109,A5) -> 46296.385 | F5: =_xlfn.MAXIFS('Task của Hưng'!I$2:I$109,'Task của Hưng'!D$2:D$109,A5) -> 46302.708
A6: Sprint 5 | B6: Nhân viên tiếp nhận thiết bị, phân công, cập nhật sửa chữa và duyệt báo giá | C6: =COUNTIF('Task của Hưng'!D$2:D$109,A6) -> 17 | D6: =SUMIF('Task của Hưng'!D$2:D$109,A6,'Task của Hưng'!K$2:K$109) -> 26 | E6: =_xlfn.MINIFS('Task của Hưng'!H$2:H$109,'Task của Hưng'!D$2:D$109,A6) -> 46303.417 | F6: =_xlfn.MAXIFS('Task của Hưng'!I$2:I$109,'Task của Hưng'!D$2:D$109,A6) -> 46309.708
A7: Sprint 6 | B7: Khách hàng xem hóa đơn, ghi nhận thanh toán và tra cứu lịch sử sửa chữa | C7: =COUNTIF('Task của Hưng'!D$2:D$109,A7) -> 12 | D7: =SUMIF('Task của Hưng'!D$2:D$109,A7,'Task của Hưng'!K$2:K$109) -> 16 | E7: =_xlfn.MINIFS('Task của Hưng'!H$2:H$109,'Task của Hưng'!D$2:D$109,A7) -> 46310.385 | F7: =_xlfn.MAXIFS('Task của Hưng'!I$2:I$109,'Task của Hưng'!D$2:D$109,A7) -> 46316.708
A8: Sprint 7 | B8: Quản lý xem thống kê; khách hàng nhận thông báo, đánh giá; bàn giao bản demo | C8: =COUNTIF('Task của Hưng'!D$2:D$109,A8) -> 16 | D8: =SUMIF('Task của Hưng'!D$2:D$109,A8,'Task của Hưng'!K$2:K$109) -> 22 | E8: =_xlfn.MINIFS('Task của Hưng'!H$2:H$109,'Task của Hưng'!D$2:D$109,A8) -> 46317.417 | F8: =_xlfn.MAXIFS('Task của Hưng'!I$2:I$109,'Task của Hưng'!D$2:D$109,A8) -> 46323.708
A9: Tổng | C9: =SUM(C2:C8) -> 108 | D9: =SUM(D2:D8) -> 142 | E9: =MIN(E2:E8) -> 46275.625 | F9: =MAX(F2:F8) -> 46323.708
